2024-08-19 08:47:44,461 - ERROR - Threaded polling exception: A request to the Telegram API was unsuccessful. Error code: 409. Description: Conflict: terminated by other getUpdates request; make sure that only one bot instance is running
2024-08-19 08:47:44,462 - ERROR - Exception traceback:
Traceback (most recent call last):
  File "c:\Users\User\AppData\Local\Programs\Python\Python312\Lib\site-packages\telebot\__init__.py", line 1215, in __threaded_polling
    polling_thread.raise_exceptions()
  File "c:\Users\User\AppData\Local\Programs\Python\Python312\Lib\site-packages\telebot\util.py", line 111, in raise_exceptions
    raise self.exception_info
  File "c:\Users\User\AppData\Local\Programs\Python\Python312\Lib\site-packages\telebot\util.py", line 93, in run
    task(*args, **kwargs)
  File "c:\Users\User\AppData\Local\Programs\Python\Python312\Lib\site-packages\telebot\__init__.py", line 677, in __retrieve_updates
    updates = self.get_updates(offset=(self.last_update_id + 1),
             ^^^^^^^^^^^^^^^^^^^^^^^^^^^^^^^^^^^^^^^^^^^^^^^^^^
  File "c:\Users\User\AppData\Local\Programs\Python\Python312\Lib\site-packages\telebot\__init__.py", line 649, in get_updates
    json_updates = apihelper.get_updates(
                   ^^^^^^^^^^^^^^^^^^^^^^
  File "c:\Users\User\AppData\Local\Programs\Python\Python312\Lib\site-packages\telebot\apihelper.py", line 330, in get_updates
    return _make_request(token, method_url, params=payload)
           ^^^^^^^^^^^^^^^^^^^^^^^^^^^^^^^^^^^^^^^^^^^^^^^^
  File "c:\Users\User\AppData\Local\Programs\Python\Python312\Lib\site-packages\telebot\apihelper.py", line 168, in _make_request
    json_result = _check_result(method_name, result)
                  ^^^^^^^^^^^^^^^^^^^^^^^^^^^^^^^^^^
  File "c:\Users\User\AppData\Local\Programs\Python\Python312\Lib\site-packages\telebot\apihelper.py", line 195, in _check_result
    raise ApiTelegramException(method_name, result, result_json)
telebot.apihelper.ApiTelegramException: A request to the Telegram API was unsuccessful. Error code: 409. Description: Conflict: terminated by other getUpdates request; make sure that only one bot instance is running

2024-08-20 15:18:18,479 - ERROR - Threaded polling exception: A request to the Telegram API was unsuccessful. Error code: 409. Description: Conflict: terminated by other getUpdates request; make sure that only one bot instance is running
2024-08-20 15:18:18,482 - ERROR - Exception traceback:
Traceback (most recent call last):
  File "c:\Users\User\AppData\Local\Programs\Python\Python312\Lib\site-packages\telebot\__init__.py", line 1215, in __threaded_polling
    polling_thread.raise_exceptions()
  File "c:\Users\User\AppData\Local\Programs\Python\Python312\Lib\site-packages\telebot\util.py", line 111, in raise_exceptions
    raise self.exception_info
  File "c:\Users\User\AppData\Local\Programs\Python\Python312\Lib\site-packages\telebot\util.py", line 93, in run
    task(*args, **kwargs)
  File "c:\Users\User\AppData\Local\Programs\Python\Python312\Lib\site-packages\telebot\__init__.py", line 677, in __retrieve_updates
    updates = self.get_updates(offset=(self.last_update_id + 1),
             ^^^^^^^^^^^^^^^^^^^^^^^^^^^^^^^^^^^^^^^^^^^^^^^^^^
  File "c:\Users\User\AppData\Local\Programs\Python\Python312\Lib\site-packages\telebot\__init__.py", line 649, in get_updates
    json_updates = apihelper.get_updates(
                   ^^^^^^^^^^^^^^^^^^^^^^
  File "c:\Users\User\AppData\Local\Programs\Python\Python312\Lib\site-packages\telebot\apihelper.py", line 330, in get_updates
    return _make_request(token, method_url, params=payload)
           ^^^^^^^^^^^^^^^^^^^^^^^^^^^^^^^^^^^^^^^^^^^^^^^^
  File "c:\Users\User\AppData\Local\Programs\Python\Python312\Lib\site-packages\telebot\apihelper.py", line 168, in _make_request
    json_result = _check_result(method_name, result)
                  ^^^^^^^^^^^^^^^^^^^^^^^^^^^^^^^^^^
  File "c:\Users\User\AppData\Local\Programs\Python\Python312\Lib\site-packages\telebot\apihelper.py", line 195, in _check_result
    raise ApiTelegramException(method_name, result, result_json)
telebot.apihelper.ApiTelegramException: A request to the Telegram API was unsuccessful. Error code: 409. Description: Conflict: terminated by other getUpdates request; make sure that only one bot instance is running

2024-09-04 14:10:06,161 - ERROR - Threaded polling exception: A request to the Telegram API was unsuccessful. Error code: 502. Description: Bad Gateway
2024-09-04 14:10:10,049 - ERROR - Exception traceback:
Traceback (most recent call last):
  File "c:\Users\User\AppData\Local\Programs\Python\Python312\Lib\site-packages\telebot\__init__.py", line 1215, in __threaded_polling
    polling_thread.raise_exceptions()
  File "c:\Users\User\AppData\Local\Programs\Python\Python312\Lib\site-packages\telebot\util.py", line 111, in raise_exceptions
    raise self.exception_info
  File "c:\Users\User\AppData\Local\Programs\Python\Python312\Lib\site-packages\telebot\util.py", line 93, in run
    task(*args, **kwargs)
  File "c:\Users\User\AppData\Local\Programs\Python\Python312\Lib\site-packages\telebot\__init__.py", line 677, in __retrieve_updates
    updates = self.get_updates(offset=(self.last_update_id + 1),
             ^^^^^^^^^^^^^^^^^^^^^^^^^^^^^^^^^^^^^^^^^^^^^^^^^^
  File "c:\Users\User\AppData\Local\Programs\Python\Python312\Lib\site-packages\telebot\__init__.py", line 649, in get_updates
    json_updates = apihelper.get_updates(
                   ^^^^^^^^^^^^^^^^^^^^^^
  File "c:\Users\User\AppData\Local\Programs\Python\Python312\Lib\site-packages\telebot\apihelper.py", line 330, in get_updates
    return _make_request(token, method_url, params=payload)
           ^^^^^^^^^^^^^^^^^^^^^^^^^^^^^^^^^^^^^^^^^^^^^^^^
  File "c:\Users\User\AppData\Local\Programs\Python\Python312\Lib\site-packages\telebot\apihelper.py", line 168, in _make_request
    json_result = _check_result(method_name, result)
                  ^^^^^^^^^^^^^^^^^^^^^^^^^^^^^^^^^^
  File "c:\Users\User\AppData\Local\Programs\Python\Python312\Lib\site-packages\telebot\apihelper.py", line 195, in _check_result
    raise ApiTelegramException(method_name, result, result_json)
telebot.apihelper.ApiTelegramException: A request to the Telegram API was unsuccessful. Error code: 502. Description: Bad Gateway

2024-09-04 14:11:32,849 - ERROR - Threaded polling exception: A request to the Telegram API was unsuccessful. Error code: 502. Description: Bad Gateway
2024-09-04 14:11:32,850 - ERROR - Exception traceback:
Traceback (most recent call last):
  File "c:\Users\User\AppData\Local\Programs\Python\Python312\Lib\site-packages\telebot\__init__.py", line 1215, in __threaded_polling
    polling_thread.raise_exceptions()
  File "c:\Users\User\AppData\Local\Programs\Python\Python312\Lib\site-packages\telebot\util.py", line 111, in raise_exceptions
    raise self.exception_info
  File "c:\Users\User\AppData\Local\Programs\Python\Python312\Lib\site-packages\telebot\util.py", line 93, in run
    task(*args, **kwargs)
  File "c:\Users\User\AppData\Local\Programs\Python\Python312\Lib\site-packages\telebot\__init__.py", line 677, in __retrieve_updates
    updates = self.get_updates(offset=(self.last_update_id + 1),
             ^^^^^^^^^^^^^^^^^^^^^^^^^^^^^^^^^^^^^^^^^^^^^^^^^^
  File "c:\Users\User\AppData\Local\Programs\Python\Python312\Lib\site-packages\telebot\__init__.py", line 649, in get_updates
    json_updates = apihelper.get_updates(
                   ^^^^^^^^^^^^^^^^^^^^^^
  File "c:\Users\User\AppData\Local\Programs\Python\Python312\Lib\site-packages\telebot\apihelper.py", line 330, in get_updates
    return _make_request(token, method_url, params=payload)
           ^^^^^^^^^^^^^^^^^^^^^^^^^^^^^^^^^^^^^^^^^^^^^^^^
  File "c:\Users\User\AppData\Local\Programs\Python\Python312\Lib\site-packages\telebot\apihelper.py", line 168, in _make_request
    json_result = _check_result(method_name, result)
                  ^^^^^^^^^^^^^^^^^^^^^^^^^^^^^^^^^^
  File "c:\Users\User\AppData\Local\Programs\Python\Python312\Lib\site-packages\telebot\apihelper.py", line 195, in _check_result
    raise ApiTelegramException(method_name, result, result_json)
telebot.apihelper.ApiTelegramException: A request to the Telegram API was unsuccessful. Error code: 502. Description: Bad Gateway

